<?xml version="1.0" encoding="UTF-8"?>
<!-- Generated by org.testng.reporters.JUnitReportReporter -->
<testsuite skipped="0" hostname="CTC-LAPT-071" name="org.test.TestGeneralStore" tests="4" failures="1" timestamp="12 May 2023 13:48:34 GMT" time="48.019" errors="0">
  <testcase name="TestAccessFormAndAddToCardWithoutProducts" time="9.231" classname="org.test.TestGeneralStore">
    <failure type="java.lang.AssertionError" message="expected:&lt;Please add some product at first&gt; but was:&lt;Please add some product at firsta&gt;">
      <![CDATA[java.lang.AssertionError: expected:<Please add some product at first> but was:<Please add some product at firsta>
at org.testng.AssertJUnit.assertEquals(AssertJUnit.java:101)
at org.testng.AssertJUnit.assertEquals(AssertJUnit.java:108)
at org.test.TestGeneralStore.TestAccessFormAndAddToCardWithoutProducts(TestGeneralStore.java:70)
at sun.reflect.NativeMethodAccessorImpl.invoke0(Native Method)
at sun.reflect.NativeMethodAccessorImpl.invoke(NativeMethodAccessorImpl.java:62)
at sun.reflect.DelegatingMethodAccessorImpl.invoke(DelegatingMethodAccessorImpl.java:43)
at java.lang.reflect.Method.invoke(Method.java:498)
at org.testng.internal.MethodInvocationHelper.invokeMethod(MethodInvocationHelper.java:124)
at org.testng.internal.Invoker.invokeMethod(Invoker.java:583)
at org.testng.internal.Invoker.invokeTestMethod(Invoker.java:719)
at org.testng.internal.Invoker.invokeTestMethods(Invoker.java:989)
at org.testng.internal.TestMethodWorker.invokeTestMethods(TestMethodWorker.java:125)
at org.testng.internal.TestMethodWorker.run(TestMethodWorker.java:109)
at org.testng.TestRunner.privateRun(TestRunner.java:648)
at org.testng.TestRunner.run(TestRunner.java:505)
at org.testng.SuiteRunner.runTest(SuiteRunner.java:455)
at org.testng.SuiteRunner.runSequentially(SuiteRunner.java:450)
at org.testng.SuiteRunner.privateRun(SuiteRunner.java:415)
at org.testng.SuiteRunner.run(SuiteRunner.java:364)
at org.testng.SuiteRunnerWorker.runSuite(SuiteRunnerWorker.java:52)
at org.testng.SuiteRunnerWorker.run(SuiteRunnerWorker.java:84)
at org.testng.TestNG.runSuitesSequentially(TestNG.java:1208)
at org.testng.TestNG.runSuitesLocally(TestNG.java:1137)
at org.testng.TestNG.runSuites(TestNG.java:1049)
at org.testng.TestNG.run(TestNG.java:1017)
at org.testng.remote.AbstractRemoteTestNG.run(AbstractRemoteTestNG.java:115)
at org.testng.remote.RemoteTestNG.initAndRun(RemoteTestNG.java:251)
at org.testng.remote.RemoteTestNG.main(RemoteTestNG.java:77)
]]>
    </failure>
  </testcase> <!-- TestAccessFormAndAddToCardWithoutProducts -->
  <testcase name="TestAccessFormAndAddProductsToCardSuccessfully" time="17.190" classname="org.test.TestGeneralStore"/>
  <testcase name="TestErrorValidationForForm" time="4.357" classname="org.test.TestGeneralStore"/>
  <testcase name="TestAccessFormAndAddProductsToCardSuccessfully" time="17.241" classname="org.test.TestGeneralStore"/>
</testsuite> <!-- org.test.TestGeneralStore -->
